Workbook

Sheet Movimentações
A1: Data | B1: Descrição | C1: Categoria | D1: Tipo | E1: Valor (R$) | F1: Contabilizar | G1: Conta | H1: Observação
A2: 46114 | B2: Uber | C2: Transporte | D2: Despesa | E2: 14.56 | F2: Sim | G2: Cartão de crédito
A3: 46115 | B3: Academia | C3: Saúde | D3: Despesa | E3: 119.9 | F3: Sim | G3: Conta corrente
A4: 46116 | B4: Supermercado | C4: Alimentação | D4: Despesa | E4: 253 | F4: Sim | G4: Cartão de crédito
A5: 46117 | B5: Salário Empresa Exemplo | C5: Salário | D5: Receita | E5: 4800 | F5: Sim | G5: Conta corrente
A6: 46117 | B6: Delivery iFood | C6: Alimentação | D6: Despesa | E6: 48.49 | F6: Sim | G6: Cartão de crédito
A7: 46118 | B7: Transferência entre contas próprias | C7: Transferência | D7: Transferência | E7: 500 | F7: Não | G7: Conta corrente | H7: Transferência entre contas próprias: não é receita nem despesa
A8: 46119 | B8: Aluguel | C8: Moradia | D8: Despesa | E8: 1500 | F8: Sim | G8: Conta corrente
A9: 46120 | B9: Netflix | C9: Assinaturas | D9: Despesa | E9: 55.9 | F9: Sim | G9: Cartão de crédito
A10: 46120 | B10: Uber | C10: Transporte | D10: Despesa | E10: 18.18 | F10: Sim | G10: Cartão de crédito
A11: 46121 | B11: Combustível | C11: Transporte | D11: Despesa | E11: 190.93 | F11: Sim | G11: Conta corrente
A12: 46122 | B12: Condomínio | C12: Moradia | D12: Despesa | E12: 420 | F12: Sim | G12: Conta corrente
A13: 46123 | B13: Spotify | C13: Assinaturas | D13: Despesa | E13: 21.9 | F13: Sim | G13: Cartão de crédito
A14: 46123 | B14: Supermercado | C14: Alimentação | D14: Despesa | E14: 308.38 | F14: Sim | G14: Cartão de crédito
A15: 46124 | B15: Conta de energia | C15: Moradia | D15: Despesa | E15: 141.25 | F15: Sim | G15: Conta corrente
A16: 46124 | B16: Delivery iFood | C16: Alimentação | D16: Despesa | E16: 69.8 | F16: Sim | G16: Cartão de crédito
A17: 46124 | B17: Conta de energia | C17: Moradia | D17: Despesa | E17: 141.25 | F17: Não | G17: Conta corrente | H17: Possível duplicidade (linha idêntica): não contabilizada
A18: 46125 | B18: Restaurante / cinema | C18: Lazer | D18: Despesa | E18: 193.32 | F18: Sim | G18: Cartão de crédito
A19: 46126 | B19: Uber | C19: Transporte | D19: Despesa | E19: 27.65 | F19: Sim | G19: Cartão de crédito
A20: 46127 | B20: Internet | C20: Moradia | D20: Despesa | E20: 109.9 | F20: Sim | G20: Conta corrente
A21: 46128 | B21: Farmácia | C21: Saúde | D21: Despesa | E21: 107.14 | F21: Sim | G21: Conta corrente
A22: 46130 | B22: Freelance design | C22: Renda extra | D22: Receita | E22: 791.83 | F22: Sim | G22: Conta corrente
A23: 46130 | B23: Supermercado | C23: Alimentação | D23: Despesa | E23: 327.06 | F23: Sim | G23: Cartão de crédito
A24: 46131 | B24: Delivery iFood | C24: Alimentação | D24: Despesa | E24: 42.09 | F24: Sim | G24: Cartão de crédito
A25: 46132 | B25: Uber | C25: Transporte | D25: Despesa | E25: 25.44 | F25: Sim | G25: Cartão de crédito
A26: 46132 | B26: Pagamento fatura cartão | C26: Cartão | D26: Pagamento de fatura | E26: 2157.08 | F26: Não | G26: Conta corrente | H26: Pagamento de fatura: não contabilizado (as compras no cartão já estão como despesas)
A27: 46133 | B27: Compra online | C27: Compras | D27: Despesa | E27: 341.75 | F27: Sim | G27: Cartão de crédito
A28: 46135 | B28: Combustível | C28: Transporte | D28: Despesa | E28: 205.27 | F28: Sim | G28: Conta corrente
A29: 46137 | B29: Supermercado | C29: Alimentação | D29: Despesa | E29: 270.63 | F29: Sim | G29: Cartão de crédito
A30: 46138 | B30: Delivery iFood | C30: Alimentação | D30: Despesa | E30: 39.4 | F30: Sim | G30: Cartão de crédito
A31: 46139 | B31: Uber | C31: Transporte | D31: Despesa | E31: 18.63 | F31: Sim | G31: Cartão de crédito
A32: 46140 | B32: Restaurante / cinema | C32: Lazer | D32: Despesa | E32: 80.91 | F32: Sim | G32: Cartão de crédito
A33: 46144 | B33: Uber | C33: Transporte | D33: Despesa | E33: 34.44 | F33: Sim | G33: Cartão de crédito
A34: 46145 | B34: Academia | C34: Saúde | D34: Despesa | E34: 119.9 | F34: Sim | G34: Conta corrente
A35: 46146 | B35: Supermercado | C35: Alimentação | D35: Despesa | E35: 238.66 | F35: Sim | G35: Cartão de crédito
A36: 46147 | B36: Salário Empresa Exemplo | C36: Salário | D36: Receita | E36: 4800 | F36: Sim | G36: Conta corrente
A37: 46147 | B37: Delivery iFood | C37: Alimentação | D37: Despesa | E37: 82.99 | F37: Sim | G37: Cartão de crédito
A38: 46148 | B38: Transferência entre contas próprias | C38: Transferência | D38: Transferência | E38: 500 | F38: Não | G38: Conta corrente | H38: Transferência entre contas próprias: não é receita nem despesa
A39: 46149 | B39: Aluguel | C39: Moradia | D39: Despesa | E39: 1500 | F39: Sim | G39: Conta corrente
A40: 46150 | B40: Netflix | C40: Assinaturas | D40: Despesa | E40: 55.9 | F40: Sim | G40: Cartão de crédito
...

Sheet Resumo
A1: Assistente Financeiro IA - Resumo financeiro
A2: Perfil: Finanças pessoais
A3: Período: 2026-04-02 a 2026-09-28
A5: Indicador | B5: Valor | C5: Como é calculado
A6: Total de receitas | B6: =SUMIFS('Movimentações'!$E$2:$E$180,'Movimentações'!$D$2:$D$180,"Receita",'Movimentações'!$F$2:$F$180,"Sim") -> 32037.7 | C6: Soma das receitas contabilizadas (aba Movimentações)
A7: Total de despesas | B7: =(SUMIFS('Movimentações'!$E$2:$E$180,'Movimentações'!$D$2:$D$180,"Despesa",'Movimentações'!$F$2:$F$180,"Sim")+SUMIFS('Movimentações'!$E$2:$E$180,'Movimentações'!$D$2:$D$180,"Pagamento de fatura",'Movimentações'!$F$2:$F$180,"Sim")) -> 29458.46 | C7: Soma das despesas contabilizadas (inclui pagamento de fatura apenas se contabilizado)
A8: Saldo do período | B8: =B6-B7 -> 2579.24 | C8: Receitas - despesas
A9: Taxa de poupança / margem do período | B9: =IF(B6=0,"n/d",B8/B6) -> 0.081 | C9: Saldo / receitas
A10: Meses no período | B10: 6 | C10: Meses de calendário entre o início e o fim do período
A11: Média mensal de receitas | B11: =B6/B10 -> 5339.62
A12: Média mensal de despesas | B12: =B7/B10 -> 4909.74
A13: Categoria de maior despesa | B13: Moradia | C13: 44.5% das despesas
A14: Transferências entre contas (fora dos totais) | B14: 6
A15: Outras movimentações não contabilizadas | B15: 7 | C15: Duplicidades e pagamentos de fatura (para evitar dupla contagem)

Sheet Categorias
A1: Categoria | B1: Valor (R$) | C1: % do total
A2: Moradia | B2: =(SUMIFS('Movimentações'!$E$2:$E$180,'Movimentações'!$D$2:$D$180,"Despesa",'Movimentações'!$F$2:$F$180,"Sim",'Movimentações'!$C$2:$C$180,$A2)+SUMIFS('Movimentações'!$E$2:$E$180,'Movimentações'!$D$2:$D$180,"Pagamento de fatura",'Movimentações'!$F$2:$F$180,"Sim",'Movimentações'!$C$2:$C$180,$A2)) -> 13116.59 | C2: =IF(SUM($B$2:$B$8)=0,0,B2/SUM($B$2:$B$8)) -> 0.445
A3: Alimentação | B3: =(SUMIFS('Movimentações'!$E$2:$E$180,'Movimentações'!$D$2:$D$180,"Despesa",'Movimentações'!$F$2:$F$180,"Sim",'Movimentações'!$C$2:$C$180,$A3)+SUMIFS('Movimentações'!$E$2:$E$180,'Movimentações'!$D$2:$D$180,"Pagamento de fatura",'Movimentações'!$F$2:$F$180,"Sim",'Movimentações'!$C$2:$C$180,$A3)) -> 7899.7 | C3: =IF(SUM($B$2:$B$8)=0,0,B3/SUM($B$2:$B$8)) -> 0.268
A4: Transporte | B4: =(SUMIFS('Movimentações'!$E$2:$E$180,'Movimentações'!$D$2:$D$180,"Despesa",'Movimentações'!$F$2:$F$180,"Sim",'Movimentações'!$C$2:$C$180,$A4)+SUMIFS('Movimentações'!$E$2:$E$180,'Movimentações'!$D$2:$D$180,"Pagamento de fatura",'Movimentações'!$F$2:$F$180,"Sim",'Movimentações'!$C$2:$C$180,$A4)) -> 3200.51 | C4: =IF(SUM($B$2:$B$8)=0,0,B4/SUM($B$2:$B$8)) -> 0.109
A5: Lazer | B5: =(SUMIFS('Movimentações'!$E$2:$E$180,'Movimentações'!$D$2:$D$180,"Despesa",'Movimentações'!$F$2:$F$180,"Sim",'Movimentações'!$C$2:$C$180,$A5)+SUMIFS('Movimentações'!$E$2:$E$180,'Movimentações'!$D$2:$D$180,"Pagamento de fatura",'Movimentações'!$F$2:$F$180,"Sim",'Movimentações'!$C$2:$C$180,$A5)) -> 1941.58 | C5: =IF(SUM($B$2:$B$8)=0,0,B5/SUM($B$2:$B$8)) -> 0.066
A6: Compras | B6: =(SUMIFS('Movimentações'!$E$2:$E$180,'Movimentações'!$D$2:$D$180,"Despesa",'Movimentações'!$F$2:$F$180,"Sim",'Movimentações'!$C$2:$C$180,$A6)+SUMIFS('Movimentações'!$E$2:$E$180,'Movimentações'!$D$2:$D$180,"Pagamento de fatura",'Movimentações'!$F$2:$F$180,"Sim",'Movimentações'!$C$2:$C$180,$A6)) -> 1543.08 | C6: =IF(SUM($B$2:$B$8)=0,0,B6/SUM($B$2:$B$8)) -> 0.052
A7: Saúde | B7: =(SUMIFS('Movimentações'!$E$2:$E$180,'Movimentações'!$D$2:$D$180,"Despesa",'Movimentações'!$F$2:$F$180,"Sim",'Movimentações'!$C$2:$C$180,$A7)+SUMIFS('Movimentações'!$E$2:$E$180,'Movimentações'!$D$2:$D$180,"Pagamento de fatura",'Movimentações'!$F$2:$F$180,"Sim",'Movimentações'!$C$2:$C$180,$A7)) -> 1290.2 | C7: =IF(SUM($B$2:$B$8)=0,0,B7/SUM($B$2:$B$8)) -> 0.044
A8: Assinaturas | B8: =(SUMIFS('Movimentações'!$E$2:$E$180,'Movimentações'!$D$2:$D$180,"Despesa",'Movimentações'!$F$2:$F$180,"Sim",'Movimentações'!$C$2:$C$180,$A8)+SUMIFS('Movimentações'!$E$2:$E$180,'Movimentações'!$D$2:$D$180,"Pagamento de fatura",'Movimentações'!$F$2:$F$180,"Sim",'Movimentações'!$C$2:$C$180,$A8)) -> 466.8 | C8: =IF(SUM($B$2:$B$8)=0,0,B8/SUM($B$2:$B$8)) -> 0.016

Sheet Análise temporal
A1: Mês | B1: Receitas | C1: Despesas | D1: Saldo | E1: Saldo acumulado
A2: 46113 | B2: =SUMIFS('Movimentações'!$E$2:$E$180,'Movimentações'!$D$2:$D$180,"Receita",'Movimentações'!$F$2:$F$180,"Sim",'Movimentações'!$A$2:$A$180,">="&$A2,'Movimentações'!$A$2:$A$180,"<"&EDATE($A2,1)) -> 5591.83 | C2: =(SUMIFS('Movimentações'!$E$2:$E$180,'Movimentações'!$D$2:$D$180,"Despesa",'Movimentações'!$F$2:$F$180,"Sim",'Movimentações'!$A$2:$A$180,">="&$A2,'Movimentações'!$A$2:$A$180,"<"&EDATE($A2,1))+SUMIFS('Movimentações'!$E$2:$E$180,'Movimentações'!$D$2:$D$180,"Pagamento de fatura",'Movimentações'!$F$2:$F$180,"Sim",'Movimentações'!$A$2:$A$180,">="&$A2,'Movimentações'!$A$2:$A$180,"<"&EDATE($A2,1))) -> 4951.48 | D2: =B2-C2 -> 640.35 | E2: =D2 -> 640.35
A3: 46143 | B3: =SUMIFS('Movimentações'!$E$2:$E$180,'Movimentações'!$D$2:$D$180,"Receita",'Movimentações'!$F$2:$F$180,"Sim",'Movimentações'!$A$2:$A$180,">="&$A3,'Movimentações'!$A$2:$A$180,"<"&EDATE($A3,1)) -> 5609.44 | C3: =(SUMIFS('Movimentações'!$E$2:$E$180,'Movimentações'!$D$2:$D$180,"Despesa",'Movimentações'!$F$2:$F$180,"Sim",'Movimentações'!$A$2:$A$180,">="&$A3,'Movimentações'!$A$2:$A$180,"<"&EDATE($A3,1))+SUMIFS('Movimentações'!$E$2:$E$180,'Movimentações'!$D$2:$D$180,"Pagamento de fatura",'Movimentações'!$F$2:$F$180,"Sim",'Movimentações'!$A$2:$A$180,">="&$A3,'Movimentações'!$A$2:$A$180,"<"&EDATE($A3,1))) -> 4832.69 | D3: =B3-C3 -> 776.75 | E3: =E2+D3 -> 1417.1
A4: 46174 | B4: =SUMIFS('Movimentações'!$E$2:$E$180,'Movimentações'!$D$2:$D$180,"Receita",'Movimentações'!$F$2:$F$180,"Sim",'Movimentações'!$A$2:$A$180,">="&$A4,'Movimentações'!$A$2:$A$180,"<"&EDATE($A4,1)) -> 4800 | C4: =(SUMIFS('Movimentações'!$E$2:$E$180,'Movimentações'!$D$2:$D$180,"Despesa",'Movimentações'!$F$2:$F$180,"Sim",'Movimentações'!$A$2:$A$180,">="&$A4,'Movimentações'!$A$2:$A$180,"<"&EDATE($A4,1))+SUMIFS('Movimentações'!$E$2:$E$180,'Movimentações'!$D$2:$D$180,"Pagamento de fatura",'Movimentações'!$F$2:$F$180,"Sim",'Movimentações'!$A$2:$A$180,">="&$A4,'Movimentações'!$A$2:$A$180,"<"&EDATE($A4,1))) -> 4842.09 | D4: =B4-C4 -> -42.09 | E4: =E3+D4 -> 1375.01
A5: 46204 | B5: =SUMIFS('Movimentações'!$E$2:$E$180,'Movimentações'!$D$2:$D$180,"Receita",'Movimentações'!$F$2:$F$180,"Sim",'Movimentações'!$A$2:$A$180,">="&$A5,'Movimentações'!$A$2:$A$180,"<"&EDATE($A5,1)) -> 5567.08 | C5: =(SUMIFS('Movimentações'!$E$2:$E$180,'Movimentações'!$D$2:$D$180,"Despesa",'Movimentações'!$F$2:$F$180,"Sim",'Movimentações'!$A$2:$A$180,">="&$A5,'Movimentações'!$A$2:$A$180,"<"&EDATE($A5,1))+SUMIFS('Movimentações'!$E$2:$E$180,'Movimentações'!$D$2:$D$180,"Pagamento de fatura",'Movimentações'!$F$2:$F$180,"Sim",'Movimentações'!$A$2:$A$180,">="&$A5,'Movimentações'!$A$2:$A$180,"<"&EDATE($A5,1))) -> 4897.02 | D5: =B5-C5 -> 670.06 | E5: =E4+D5 -> 2045.07
A6: 46235 | B6: =SUMIFS('Movimentações'!$E$2:$E$180,'Movimentações'!$D$2:$D$180,"Receita",'Movimentações'!$F$2:$F$180,"Sim",'Movimentações'!$A$2:$A$180,">="&$A6,'Movimentações'!$A$2:$A$180,"<"&EDATE($A6,1)) -> 5669.35 | C6: =(SUMIFS('Movimentações'!$E$2:$E$180,'Movimentações'!$D$2:$D$180,"Despesa",'Movimentações'!$F$2:$F$180,"Sim",'Movimentações'!$A$2:$A$180,">="&$A6,'Movimentações'!$A$2:$A$180,"<"&EDATE($A6,1))+SUMIFS('Movimentações'!$E$2:$E$180,'Movimentações'!$D$2:$D$180,"Pagamento de fatura",'Movimentações'!$F$2:$F$180,"Sim",'Movimentações'!$A$2:$A$180,">="&$A6,'Movimentações'!$A$2:$A$180,"<"&EDATE($A6,1))) -> 4892.65 | D6: =B6-C6 -> 776.7 | E6: =E5+D6 -> 2821.77
A7: 46266 | B7: =SUMIFS('Movimentações'!$E$2:$E$180,'Movimentações'!$D$2:$D$180,"Receita",'Movimentações'!$F$2:$F$180,"Sim",'Movimentações'!$A$2:$A$180,">="&$A7,'Movimentações'!$A$2:$A$180,"<"&EDATE($A7,1)) -> 4800 | C7: =(SUMIFS('Movimentações'!$E$2:$E$180,'Movimentações'!$D$2:$D$180,"Despesa",'Movimentações'!$F$2:$F$180,"Sim",'Movimentações'!$A$2:$A$180,">="&$A7,'Movimentações'!$A$2:$A$180,"<"&EDATE($A7,1))+SUMIFS('Movimentações'!$E$2:$E$180,'Movimentações'!$D$2:$D$180,"Pagamento de fatura",'Movimentações'!$F$2:$F$180,"Sim",'Movimentações'!$A$2:$A$180,">="&$A7,'Movimentações'!$A$2:$A$180,"<"&EDATE($A7,1))) -> 5042.53 | D7: =B7-C7 -> -242.53 | E7: =E6+D7 -> 2579.24

Sheet Recomendações
A1: Tipo | B1: Título | C1: Detalhe | D1: Premissas / estimativas
A2: Fato | B2: Resultado do período | C2: Total de receitas R$ 32.037,70 menos total de despesas R$ 29.458,46 = R$ 2.579,24. | D2: Somente movimentações contabilizadas; transferências entre contas próprias e duplicidades ficam de fora.
A3: Estimativa | B3: Reduzir 10% em Moradia | C3: Moradia representa 44.5% das despesas (média de R$ 2.186,10/mês). Cortar 10% economizaria cerca de R$ 218,61 por mês, ou R$ 2.623,32 por ano. | D3: Média mensal sobre 6 mês(es); reduz 10% sem outras mudanças; sem inflação.
A4: Recomendação | B4: Revise despesas recorrentes | C4: Foram identificados gastos que se repetem todo mês: Aluguel, Supermercado, Condomínio, Combustível. Confirme se todos ainda fazem sentido. Assinaturas/serviços somam ~R$ 77,80/mês. | D4: Recorrente = mesma descrição em 3+ meses com valor estável (variação até 20%).

Sheet Simulação
A1: Categoria | B1: Média mensal atual | C1: Redução (%) | D1: Economia mensal | E1: Economia anual
A2: Alimentação | B2: 1316.62 | C2: 0.15 | D2: =B2*C2 -> 197.49 | E2: =D2*12 -> 2369.91
A3: Transporte | B3: 533.42 | C3: 0.1 | D3: =B3*C3 -> 53.34 | E3: =D3*12 -> 640.1
A5: Aumento de receita simulado (%) | B5: 0.05
A7: Indicador (mensal) | B7: Atual | C7: Projetado
A8: Receita | B8: 5339.62 | C8: =B8*(1+B5) -> 5606.6
A9: Despesa | B9: 4909.74 | C9: =B9-SUM(D2:D3) -> 4658.91
A10: Saldo | B10: =B8-B9 -> 429.88 | C10: =C8-C9 -> 947.7
A11: Ganho mensal estimado | C11: =C10-B10 -> 517.82
A12: Ganho anual estimado | C12: =C11*12 -> 6213.78
A14: Valores simulados são estimativas baseadas na média mensal do período analisado. Não garantem resultados futuros: preços, renda e hábitos podem mudar.

Sheet Avisos
A1: Avisos e premissas
A3: Gerado em 17/10/2026 20:53 pelo Assistente Financeiro IA (protótipo/MVP).
A4: Transferências entre contas próprias não são receita nem despesa e ficam fora dos totais.
A5: Linhas com 'Contabilizar = Não' (duplicidades, pagamento de fatura com compras já lançadas) não entram nos totais. Altere para 'Sim'/'Não' e as fórmulas recalculam.
A6: Totais e gráficos são fórmulas/gráficos nativos do Excel ligados às abas de dados: edite os dados e os gráficos se atualizam.
A7: Recomendações e simulações são estimativas baseadas nos dados do período e não garantem resultados futuros. Não substituem orientação profissional.
